<?xml version="1.0"?>
<robot name="kxrl2l2a6h2m"
       xmlns:xi="http://www.w3.org/2001/XInclude">
  <link name="bodyset94472077639384">
    <visual>
      <origin xyz="0 0 0.1205" rpy="0 -0 0"/>
      <geometry>
        <mesh filename="package://kxr_models/meshes/kxrl2l2a6h2m/bodyset94472077639384_mesh.dae" scale="1 1 1" />
      </geometry>
    </visual>
    <collision>
      <origin xyz="0 0 0.1205" rpy="0 -0 0"/>
      <geometry>
        <mesh filename="package://kxr_models/meshes/kxrl2l2a6h2m/bodyset94472077639384_mesh.dae" scale="1 1 1" />
      </geometry>
    </collision>
    <inertial>
      <mass value="0.437124" />
      <origin xyz="-0.005319 2.13443e-10 0.029207" rpy="0 -0 0"/>
      <inertia ixx="0.001306" ixy="-8.28224e-06" ixz="-1.69917e-06" iyy="0.001381" iyz="1.4569e-06" izz="0.002216"/>
    </inertial>
  </link>
  <link name="HEAD_LINK0">
    <visual>
      <origin xyz="-0.00725 0 0.084" rpy="0 -0 0"/>
      <geometry>
        <mesh filename="package://kxr_models/meshes/kxrl2l2a6h2m/HEAD_LINK0_mesh.dae" scale="1 1 1" />
      </geometry>
    </visual>
    <collision>
      <origin xyz="-0.00725 0 0.084" rpy="0 -0 0"/>
      <geometry>
        <mesh filename="package://kxr_models/meshes/kxrl2l2a6h2m/HEAD_LINK0_mesh.dae" scale="1 1 1" />
      </geometry>
    </collision>
    <inertial>
      <mass value="0.037398" />
      <origin xyz="0 1.22056e-18 0.023093" rpy="0 -0 0"/>
      <inertia ixx="6.28707e-05" ixy="3.12188e-21" ixz="8.61164e-09" iyy="6.69539e-05" iyz="-5.25778e-09" izz="2.5436e-05"/>
    </inertial>
  </link>
  <link name="HEAD_LINK1">
    <visual>
      <origin xyz="0 0 0.036" rpy="0 -0 0"/>
      <geometry>
        <mesh filename="package://kxr_models/meshes/kxrl2l2a6h2m/HEAD_LINK1_mesh.dae" scale="1 1 1" />
      </geometry>
    </visual>
    <collision>
      <origin xyz="0 0 0.036" rpy="0 -0 0"/>
      <geometry>
        <mesh filename="package://kxr_models/meshes/kxrl2l2a6h2m/HEAD_LINK1_mesh.dae" scale="1 1 1" />
      </geometry>
    </collision>
    <inertial>
      <mass value="0.160516" />
      <origin xyz="0.001469 -6.19726e-19 0.171559" rpy="0 -0 0"/>
      <inertia ixx="0.00092" ixy="-1.79922e-07" ixz="-6.65543e-08" iyy="0.000849" iyz="-1.79583e-08" izz="0.000187"/>
    </inertial>
  </link>
  <link name="LARM_LINK0">
    <visual>
      <origin xyz="0.00725 0.0465 0.069" rpy="0 -0 0"/>
      <geometry>
        <mesh filename="package://kxr_models/meshes/kxrl2l2a6h2m/LARM_LINK0_mesh.dae" scale="1 1 1" />
      </geometry>
    </visual>
    <collision>
      <origin xyz="0.00725 0.0465 0.069" rpy="0 -0 0"/>
      <geometry>
        <mesh filename="package://kxr_models/meshes/kxrl2l2a6h2m/LARM_LINK0_mesh.dae" scale="1 1 1" />
      </geometry>
    </collision>
    <inertial>
      <mass value="0.011619" />
      <origin xyz="1.73472e-18 0 0.012925" rpy="0 -0 0"/>
      <inertia ixx="3.94725e-05" ixy="-2.05366e-09" ixz="1.93423e-09" iyy="2.58467e-05" iyz="2.68346e-09" izz="1.89272e-05"/>
    </inertial>
  </link>
  <link name="LARM_LINK1">
    <visual>
      <origin xyz="0 0.031 0" rpy="0 -0 0"/>
      <geometry>
        <mesh filename="package://kxr_models/meshes/kxrl2l2a6h2m/LARM_LINK1_mesh.dae" scale="1 1 1" />
      </geometry>
    </visual>
    <collision>
      <origin xyz="0 0.031 0" rpy="0 -0 0"/>
      <geometry>
        <mesh filename="package://kxr_models/meshes/kxrl2l2a6h2m/LARM_LINK1_mesh.dae" scale="1 1 1" />
      </geometry>
    </collision>
    <inertial>
      <mass value="0.078374" />
      <origin xyz="-0.013148 0.008556 1.38778e-17" rpy="0 -0 0"/>
      <inertia ixx="8.84213e-05" ixy="-6.06237e-08" ixz="1.1156e-07" iyy="6.51421e-05" iyz="1.21718e-07" izz="8.07487e-05"/>
    </inertial>
  </link>
  <link name="LARM_LINK2">
    <visual>
      <origin xyz="0 0 -0.015" rpy="0 -0 0"/>
      <geometry>
        <mesh filename="package://kxr_models/meshes/kxrl2l2a6h2m/LARM_LINK2_mesh.dae" scale="1 1 1" />
      </geometry>
    </visual>
    <collision>
      <origin xyz="0 0 -0.015" rpy="0 -0 0"/>
      <geometry>
        <mesh filename="package://kxr_models/meshes/kxrl2l2a6h2m/LARM_LINK2_mesh.dae" scale="1 1 1" />
      </geometry>
    </collision>
    <inertial>
      <mass value="0.012939" />
      <origin xyz="0 0 0.016427" rpy="0 -0 0"/>
      <inertia ixx="4.20135e-05" ixy="-3.18804e-09" ixz="3.84132e-09" iyy="1.71658e-05" iyz="-4.7056e-09" izz="2.91052e-05"/>
    </inertial>
  </link>
  <link name="LARM_LINK3">
    <visual>
      <origin xyz="0 0 -0.041" rpy="0 -0 0"/>
      <geometry>
        <mesh filename="package://kxr_models/meshes/kxrl2l2a6h2m/LARM_LINK3_mesh.dae" scale="1 1 1" />
      </geometry>
    </visual>
    <collision>
      <origin xyz="0 0 -0.041" rpy="0 -0 0"/>
      <geometry>
        <mesh filename="package://kxr_models/meshes/kxrl2l2a6h2m/LARM_LINK3_mesh.dae" scale="1 1 1" />
      </geometry>
    </collision>
    <inertial>
      <mass value="0.05298" />
      <origin xyz="0.014792 0 -0.005477" rpy="0 -0 0"/>
      <inertia ixx="6.26397e-05" ixy="5.66051e-08" ixz="1.81381e-08" iyy="2.76781e-05" iyz="-6.74218e-07" izz="6.53223e-05"/>
    </inertial>
  </link>
  <link name="LARM_LINK4">
    <visual>
      <origin xyz="-0.0235 0 -0.043" rpy="0 -0 0"/>
      <geometry>
        <mesh filename="package://kxr_models/meshes/kxrl2l2a6h2m/LARM_LINK4_mesh.dae" scale="1 1 1" />
      </geometry>
    </visual>
    <collision>
      <origin xyz="-0.0235 0 -0.043" rpy="0 -0 0"/>
      <geometry>
        <mesh filename="package://kxr_models/meshes/kxrl2l2a6h2m/LARM_LINK4_mesh.dae" scale="1 1 1" />
      </geometry>
    </collision>
    <inertial>
      <mass value="0.078374" />
      <origin xyz="0 0.013148 -0.008556" rpy="0 -0 0"/>
      <inertia ixx="7.68304e-05" ixy="-6.06237e-08" ixz="1.1156e-07" iyy="5.20635e-05" iyz="1.21718e-07" izz="8.18295e-05"/>
    </inertial>
  </link>
  <link name="LARM_LINK5">
    <visual>
      <origin xyz="0.015 0 0" rpy="0 -0 0"/>
      <geometry>
        <mesh filename="package://kxr_models/meshes/kxrl2l2a6h2m/LARM_LINK5_mesh.dae" scale="1 1 1" />
      </geometry>
    </visual>
    <collision>
      <origin xyz="0.015 0 0" rpy="0 -0 0"/>
      <geometry>
        <mesh filename="package://kxr_models/meshes/kxrl2l2a6h2m/LARM_LINK5_mesh.dae" scale="1 1 1" />
      </geometry>
    </collision>
    <inertial>
      <mass value="0.042589" />
      <origin xyz="0.019552 0.079931 -0.03" rpy="0 -0 0"/>
      <inertia ixx="6.06965e-05" ixy="-5.22786e-23" ixz="8.61164e-09" iyy="2.91624e-05" iyz="-5.25778e-09" izz="6.59873e-05"/>
    </inertial>
  </link>
  <link name="LARM_LINK6">
    <visual>
      <origin xyz="0.0315 0.0105 0" rpy="0 -0 0"/>
      <geometry>
        <mesh filename="package://kxr_models/meshes/kxrl2l2a6h2m/LARM_LINK6_mesh.dae" scale="1 1 1" />
      </geometry>
    </visual>
    <collision>
      <origin xyz="0.0315 0.0105 0" rpy="0 -0 0"/>
      <geometry>
        <mesh filename="package://kxr_models/meshes/kxrl2l2a6h2m/LARM_LINK6_mesh.dae" scale="1 1 1" />
      </geometry>
    </collision>
    <inertial>
      <mass value="0.013267" />
      <origin xyz="0.048523 0.016764 3.46945e-18" rpy="0 -0 0"/>
      <inertia ixx="5.60417e-05" ixy="-2.54028e-09" ixz="-2.35822e-09" iyy="2.2066e-05" iyz="-1.52851e-07" izz="6.47415e-05"/>
    </inertial>
  </link>
  <link name="LARM_LINK7">
    <visual>
      <origin xyz="0.0315 -0.012979 0" rpy="0 -0 0"/>
      <geometry>
        <mesh filename="package://kxr_models/meshes/kxrl2l2a6h2m/LARM_LINK7_mesh.dae" scale="1 1 1" />
      </geometry>
    </visual>
    <collision>
      <origin xyz="0.0315 -0.012979 0" rpy="0 -0 0"/>
      <geometry>
        <mesh filename="package://kxr_models/meshes/kxrl2l2a6h2m/LARM_LINK7_mesh.dae" scale="1 1 1" />
      </geometry>
    </collision>
    <inertial>
      <mass value="0.013267" />
      <origin xyz="0.048523 -0.019242 2.42861e-17" rpy="0 -0 0"/>
      <inertia ixx="2.83996e-05" ixy="-2.54028e-09" ixz="-2.35822e-09" iyy="2.2066e-05" iyz="-1.52851e-07" izz="3.70994e-05"/>
    </inertial>
  </link>
  <link name="LLEG_LINK0">
    <visual>
      <origin xyz="0 0.034 -0.0565" rpy="0 -0 0"/>
      <geometry>
        <mesh filename="package://kxr_models/meshes/kxrl2l2a6h2m/LLEG_LINK0_mesh.dae" scale="1 1 1" />
      </geometry>
    </visual>
    <collision>
      <origin xyz="0 0.034 -0.0565" rpy="0 -0 0"/>
      <geometry>
        <mesh filename="package://kxr_models/meshes/kxrl2l2a6h2m/LLEG_LINK0_mesh.dae" scale="1 1 1" />
      </geometry>
    </collision>
    <inertial>
      <mass value="0.036864" />
      <origin xyz="1.41734e-18 0 0.017401" rpy="0 -0 0"/>
      <inertia ixx="3.95184e-05" ixy="9.57875e-22" ixz="8.61164e-09" iyy="3.94439e-05" iyz="-5.25778e-09" izz="2.97098e-05"/>
    </inertial>
  </link>
  <link name="LLEG_LINK1">
    <visual>
      <origin xyz="0 0 -0.033" rpy="0 -0 0"/>
      <geometry>
        <mesh filename="package://kxr_models/meshes/kxrl2l2a6h2m/LLEG_LINK1_mesh.dae" scale="1 1 1" />
      </geometry>
    </visual>
    <collision>
      <origin xyz="0 0 -0.033" rpy="0 -0 0"/>
      <geometry>
        <mesh filename="package://kxr_models/meshes/kxrl2l2a6h2m/LLEG_LINK1_mesh.dae" scale="1 1 1" />
      </geometry>
    </collision>
    <inertial>
      <mass value="0.038432" />
      <origin xyz="-1.84881e-19 0.007514 -0.025416" rpy="0 -0 0"/>
      <inertia ixx="0.000267" ixy="3.74795e-08" ixz="-1.78739e-07" iyy="0.000114" iyz="-5.24227e-07" izz="0.000159"/>
    </inertial>
  </link>
  <link name="RARM_LINK0">
    <visual>
      <origin xyz="0.00725 -0.0465 0.069" rpy="0 -0 0"/>
      <geometry>
        <mesh filename="package://kxr_models/meshes/kxrl2l2a6h2m/RARM_LINK0_mesh.dae" scale="1 1 1" />
      </geometry>
    </visual>
    <collision>
      <origin xyz="0.00725 -0.0465 0.069" rpy="0 -0 0"/>
      <geometry>
        <mesh filename="package://kxr_models/meshes/kxrl2l2a6h2m/RARM_LINK0_mesh.dae" scale="1 1 1" />
      </geometry>
    </collision>
    <inertial>
      <mass value="0.011619" />
      <origin xyz="1.73472e-18 0 0.012925" rpy="0 -0 0"/>
      <inertia ixx="3.94725e-05" ixy="-2.05366e-09" ixz="1.93423e-09" iyy="2.58467e-05" iyz="2.68346e-09" izz="1.89272e-05"/>
    </inertial>
  </link>
  <link name="RARM_LINK1">
    <visual>
      <origin xyz="0 -0.031 0" rpy="0 -0 0"/>
      <geometry>
        <mesh filename="package://kxr_models/meshes/kxrl2l2a6h2m/RARM_LINK1_mesh.dae" scale="1 1 1" />
      </geometry>
    </visual>
    <collision>
      <origin xyz="0 -0.031 0" rpy="0 -0 0"/>
      <geometry>
        <mesh filename="package://kxr_models/meshes/kxrl2l2a6h2m/RARM_LINK1_mesh.dae" scale="1 1 1" />
      </geometry>
    </collision>
    <inertial>
      <mass value="0.078374" />
      <origin xyz="-0.013148 -0.008556 1.38778e-17" rpy="0 -0 0"/>
      <inertia ixx="8.84213e-05" ixy="-6.06237e-08" ixz="1.1156e-07" iyy="6.51421e-05" iyz="1.21718e-07" izz="8.07487e-05"/>
    </inertial>
  </link>
  <link name="RARM_LINK2">
    <visual>
      <origin xyz="0 0 -0.015" rpy="0 -0 0"/>
      <geometry>
        <mesh filename="package://kxr_models/meshes/kxrl2l2a6h2m/RARM_LINK2_mesh.dae" scale="1 1 1" />
      </geometry>
    </visual>
    <collision>
      <origin xyz="0 0 -0.015" rpy="0 -0 0"/>
      <geometry>
        <mesh filename="package://kxr_models/meshes/kxrl2l2a6h2m/RARM_LINK2_mesh.dae" scale="1 1 1" />
      </geometry>
    </collision>
    <inertial>
      <mass value="0.012939" />
      <origin xyz="0 0 0.016427" rpy="0 -0 0"/>
      <inertia ixx="4.20135e-05" ixy="-3.18804e-09" ixz="3.84132e-09" iyy="1.71658e-05" iyz="-4.7056e-09" izz="2.91052e-05"/>
    </inertial>
  </link>
  <link name="RARM_LINK3">
    <visual>
      <origin xyz="0 0 -0.041" rpy="0 -0 0"/>
      <geometry>
        <mesh filename="package://kxr_models/meshes/kxrl2l2a6h2m/RARM_LINK3_mesh.dae" scale="1 1 1" />
      </geometry>
    </visual>
    <collision>
      <origin xyz="0 0 -0.041" rpy="0 -0 0"/>
      <geometry>
        <mesh filename="package://kxr_models/meshes/kxrl2l2a6h2m/RARM_LINK3_mesh.dae" scale="1 1 1" />
      </geometry>
    </collision>
    <inertial>
      <mass value="0.05298" />
      <origin xyz="0.014792 0 -0.005477" rpy="0 -0 0"/>
      <inertia ixx="6.26397e-05" ixy="5.66051e-08" ixz="1.81381e-08" iyy="2.76781e-05" iyz="-6.74218e-07" izz="6.53223e-05"/>
    </inertial>
  </link>
  <link name="RARM_LINK4">
    <visual>
      <origin xyz="-0.0235 0 -0.043" rpy="0 -0 0"/>
      <geometry>
        <mesh filename="package://kxr_models/meshes/kxrl2l2a6h2m/RARM_LINK4_mesh.dae" scale="1 1 1" />
      </geometry>
    </visual>
    <collision>
      <origin xyz="-0.0235 0 -0.043" rpy="0 -0 0"/>
      <geometry>
        <mesh filename="package://kxr_models/meshes/kxrl2l2a6h2m/RARM_LINK4_mesh.dae" scale="1 1 1" />
      </geometry>
    </collision>
    <inertial>
      <mass value="0.078374" />
      <origin xyz="0 -0.013148 -0.008556" rpy="0 -0 0"/>
      <inertia ixx="7.68304e-05" ixy="-6.06237e-08" ixz="1.1156e-07" iyy="5.20635e-05" iyz="1.21718e-07" izz="8.18295e-05"/>
    </inertial>
  </link>
  <link name="RARM_LINK5">
    <visual>
      <origin xyz="0.015 0 0" rpy="0 -0 0"/>
      <geometry>
        <mesh filename="package://kxr_models/meshes/kxrl2l2a6h2m/RARM_LINK5_mesh.dae" scale="1 1 1" />
      </geometry>
    </visual>
    <collision>
      <origin xyz="0.015 0 0" rpy="0 -0 0"/>
      <geometry>
        <mesh filename="package://kxr_models/meshes/kxrl2l2a6h2m/RARM_LINK5_mesh.dae" scale="1 1 1" />
      </geometry>
    </collision>
    <inertial>
      <mass value="0.042589" />
      <origin xyz="0.019552 -0.079931 -0.03" rpy="0 -0 0"/>
      <inertia ixx="6.06965e-05" ixy="-5.22786e-23" ixz="8.61164e-09" iyy="2.91624e-05" iyz="-5.25778e-09" izz="6.59873e-05"/>
    </inertial>
  </link>
  <link name="RARM_LINK6">
    <visual>
      <origin xyz="0.0315 -0.0105 0" rpy="0 -0 0"/>
      <geometry>
        <mesh filename="package://kxr_models/meshes/kxrl2l2a6h2m/RARM_LINK6_mesh.dae" scale="1 1 1" />
      </geometry>
    </visual>
    <collision>
      <origin xyz="0.0315 -0.0105 0" rpy="0 -0 0"/>
      <geometry>
        <mesh filename="package://kxr_models/meshes/kxrl2l2a6h2m/RARM_LINK6_mesh.dae" scale="1 1 1" />
      </geometry>
    </collision>
    <inertial>
      <mass value="0.013267" />
      <origin xyz="0.048523 -0.016764 2.08167e-17" rpy="0 -0 0"/>
      <inertia ixx="5.60417e-05" ixy="-2.54028e-09" ixz="-2.35822e-09" iyy="2.2066e-05" iyz="-1.52851e-07" izz="6.47415e-05"/>
    </inertial>
  </link>
  <link name="RARM_LINK7">
    <visual>
      <origin xyz="0.0315 0.012979 0" rpy="0 -0 0"/>
      <geometry>
        <mesh filename="package://kxr_models/meshes/kxrl2l2a6h2m/RARM_LINK7_mesh.dae" scale="1 1 1" />
      </geometry>
    </visual>
    <collision>
      <origin xyz="0.0315 0.012979 0" rpy="0 -0 0"/>
      <geometry>
        <mesh filename="package://kxr_models/meshes/kxrl2l2a6h2m/RARM_LINK7_mesh.dae" scale="1 1 1" />
      </geometry>
    </collision>
    <inertial>
      <mass value="0.013267" />
      <origin xyz="0.048523 0.019242 3.1225e-17" rpy="0 -0 0"/>
      <inertia ixx="2.83996e-05" ixy="-2.54028e-09" ixz="-2.35822e-09" iyy="2.2066e-05" iyz="-1.52851e-07" izz="3.70994e-05"/>
    </inertial>
  </link>
  <link name="RLEG_LINK0">
    <visual>
      <origin xyz="0 -0.034 -0.0565" rpy="0 -0 0"/>
      <geometry>
        <mesh filename="package://kxr_models/meshes/kxrl2l2a6h2m/RLEG_LINK0_mesh.dae" scale="1 1 1" />
      </geometry>
    </visual>
    <collision>
      <origin xyz="0 -0.034 -0.0565" rpy="0 -0 0"/>
      <geometry>
        <mesh filename="package://kxr_models/meshes/kxrl2l2a6h2m/RLEG_LINK0_mesh.dae" scale="1 1 1" />
      </geometry>
    </collision>
    <inertial>
      <mass value="0.036864" />
      <origin xyz="1.41734e-18 0 0.017401" rpy="0 -0 0"/>
      <inertia ixx="3.95184e-05" ixy="9.57875e-22" ixz="8.61164e-09" iyy="3.94439e-05" iyz="-5.25778e-09" izz="2.97098e-05"/>
    </inertial>
  </link>
  <link name="RLEG_LINK1">
    <visual>
      <origin xyz="0 0 -0.033" rpy="0 -0 0"/>
      <geometry>
        <mesh filename="package://kxr_models/meshes/kxrl2l2a6h2m/RLEG_LINK1_mesh.dae" scale="1 1 1" />
      </geometry>
    </visual>
    <collision>
      <origin xyz="0 0 -0.033" rpy="0 -0 0"/>
      <geometry>
        <mesh filename="package://kxr_models/meshes/kxrl2l2a6h2m/RLEG_LINK1_mesh.dae" scale="1 1 1" />
      </geometry>
    </collision>
    <inertial>
      <mass value="0.038432" />
      <origin xyz="3.8825e-18 -0.007514 -0.025416" rpy="0 -0 0"/>
      <inertia ixx="0.000267" ixy="3.74795e-08" ixz="-1.78739e-07" iyy="0.000114" iyz="-5.24227e-07" izz="0.000159"/>
    </inertial>
  </link>
  <joint name="HEAD_JOINT0" type="revolute">
    <parent link="bodyset94472077639384"/>
    <child  link="HEAD_LINK0"/>
    <origin xyz="-0.00725 0 0.084" rpy="0 -0 0 "/>
    <axis   xyz="0 0 -1"/>
    <limit lower="-2.96706" upper="2.96706" effort="0.656248" velocity="7.47998" />
    <dynamics damping="0.2" friction="0" />
  </joint>
  <joint name="HEAD_JOINT1" type="revolute">
    <parent link="HEAD_LINK0"/>
    <child  link="HEAD_LINK1"/>
    <origin xyz="0 0 0.036" rpy="0 -0 0 "/>
    <axis   xyz="0 -1 0"/>
    <limit lower="-2.0944" upper="2.0944" effort="0.656248" velocity="7.47998" />
    <dynamics damping="0.2" friction="0" />
  </joint>
  <joint name="LARM_JOINT0" type="revolute">
    <parent link="bodyset94472077639384"/>
    <child  link="LARM_LINK0"/>
    <origin xyz="0.00725 0.0465 0.069" rpy="0 -0 0 "/>
    <axis   xyz="0 -1 0"/>
    <limit lower="-3.14159" upper="3.14159" effort="0.656248" velocity="7.47998" />
    <dynamics damping="0.2" friction="0" />
  </joint>
  <joint name="LARM_JOINT1" type="revolute">
    <parent link="LARM_LINK0"/>
    <child  link="LARM_LINK1"/>
    <origin xyz="0 0.031 0" rpy="0 -0 0 "/>
    <axis   xyz="1 0 0"/>
    <limit lower="-1.91986" upper="1.91986" effort="0.656248" velocity="7.47998" />
    <dynamics damping="0.2" friction="0" />
  </joint>
  <joint name="LARM_JOINT2" type="revolute">
    <parent link="LARM_LINK1"/>
    <child  link="LARM_LINK2"/>
    <origin xyz="0 0 -0.015" rpy="0 -0 0 "/>
    <axis   xyz="0 0 1"/>
    <limit lower="-2.35619" upper="2.35619" effort="0.656248" velocity="7.47998" />
    <dynamics damping="0.2" friction="0" />
  </joint>
  <joint name="LARM_JOINT3" type="revolute">
    <parent link="LARM_LINK2"/>
    <child  link="LARM_LINK3"/>
    <origin xyz="0 0 -0.041" rpy="0 -0 0 "/>
    <axis   xyz="0 1 0"/>
    <limit lower="-2.96706" upper="2.96706" effort="0.656248" velocity="7.47998" />
    <dynamics damping="0.2" friction="0" />
  </joint>
  <joint name="LARM_JOINT4" type="revolute">
    <parent link="LARM_LINK3"/>
    <child  link="LARM_LINK4"/>
    <origin xyz="-0.0235 0 -0.043" rpy="0 -0 0 "/>
    <axis   xyz="0 -1 0"/>
    <limit lower="-2.18166" upper="1.74533" effort="0.656248" velocity="7.47998" />
    <dynamics damping="0.2" friction="0" />
  </joint>
  <joint name="LARM_JOINT5" type="revolute">
    <parent link="LARM_LINK4"/>
    <child  link="LARM_LINK5"/>
    <origin xyz="0.015 0 0" rpy="0 -0 0 "/>
    <axis   xyz="-1 0 0"/>
    <limit lower="-2.35619" upper="2.35619" effort="0.656248" velocity="7.47998" />
    <dynamics damping="0.2" friction="0" />
  </joint>
  <joint name="LARM_JOINT6" type="revolute">
    <parent link="LARM_LINK5"/>
    <child  link="LARM_LINK6"/>
    <origin xyz="0.0315 0.0105 0" rpy="0 -0 0 "/>
    <axis   xyz="2.22045e-16 0 1"/>
    <limit lower="-1.74533" upper="1.74533" effort="0.656248" velocity="7.47998" />
    <dynamics damping="0.2" friction="0" />
  </joint>
  <joint name="LARM_JOINT7" type="revolute">
    <parent link="LARM_LINK5"/>
    <child  link="LARM_LINK7"/>
    <origin xyz="0.0315 -0.012979 0" rpy="0 -0 0 "/>
    <axis   xyz="0 0 -1"/>
    <!-- <mimic joint="LARM_JOINT6" multiplier="1" /> -->
    <limit lower="-1.74533" upper="1.74533" effort="0.656248" velocity="7.47998" />
    <dynamics damping="0.2" friction="0" />
  </joint>
  <joint name="LLEG_JOINT0" type="revolute">
    <parent link="bodyset94472077639384"/>
    <child  link="LLEG_LINK0"/>
    <origin xyz="0 0.034 -0.0565" rpy="0 -0 0 "/>
    <axis   xyz="0 0 1"/>
    <limit lower="-1.91986" upper="1.91986" effort="0.656248" velocity="7.47998" />
    <dynamics damping="0.2" friction="0" />
  </joint>
  <joint name="LLEG_JOINT1" type="revolute">
    <parent link="LLEG_LINK0"/>
    <child  link="LLEG_LINK1"/>
    <origin xyz="0 0 -0.033" rpy="0 -0 0 "/>
    <axis   xyz="-1 0 0"/>
    <limit lower="-1.91986" upper="1.91986" effort="0.656248" velocity="7.47998" />
    <dynamics damping="0.2" friction="0" />
  </joint>
  <joint name="RARM_JOINT0" type="revolute">
    <parent link="bodyset94472077639384"/>
    <child  link="RARM_LINK0"/>
    <origin xyz="0.00725 -0.0465 0.069" rpy="0 -0 0 "/>
    <axis   xyz="0 1 0"/>
    <limit lower="-3.14159" upper="3.14159" effort="0.656248" velocity="7.47998" />
    <dynamics damping="0.2" friction="0" />
  </joint>
  <joint name="RARM_JOINT1" type="revolute">
    <parent link="RARM_LINK0"/>
    <child  link="RARM_LINK1"/>
    <origin xyz="0 -0.031 0" rpy="0 -0 0 "/>
    <axis   xyz="1 0 0"/>
    <limit lower="-1.91986" upper="1.91986" effort="0.656248" velocity="7.47998" />
    <dynamics damping="0.2" friction="0" />
  </joint>
  <joint name="RARM_JOINT2" type="revolute">
    <parent link="RARM_LINK1"/>
    <child  link="RARM_LINK2"/>
    <origin xyz="0 0 -0.015" rpy="0 -0 0 "/>
    <axis   xyz="0 0 1"/>
    <limit lower="-2.35619" upper="2.35619" effort="0.656248" velocity="7.47998" />
    <dynamics damping="0.2" friction="0" />
  </joint>
  <joint name="RARM_JOINT3" type="revolute">
    <parent link="RARM_LINK2"/>
    <child  link="RARM_LINK3"/>
    <origin xyz="0 0 -0.041" rpy="0 -0 0 "/>
    <axis   xyz="0 1 0"/>
    <limit lower="-2.96706" upper="2.96706" effort="0.656248" velocity="7.47998" />
    <dynamics damping="0.2" friction="0" />
  </joint>
  <joint name="RARM_JOINT4" type="revolute">
    <parent link="RARM_LINK3"/>
    <child  link="RARM_LINK4"/>
    <origin xyz="-0.0235 0 -0.043" rpy="0 -0 0 "/>
    <axis   xyz="0 1 0"/>
    <limit lower="-2.18166" upper="1.74533" effort="0.656248" velocity="7.47998" />
    <dynamics damping="0.2" friction="0" />
  </joint>
  <joint name="RARM_JOINT5" type="revolute">
    <parent link="RARM_LINK4"/>
    <child  link="RARM_LINK5"/>
    <origin xyz="0.015 0 0" rpy="0 -0 0 "/>
    <axis   xyz="-1 0 0"/>
    <limit lower="-2.35619" upper="2.35619" effort="0.656248" velocity="7.47998" />
    <dynamics damping="0.2" friction="0" />
  </joint>
  <joint name="RARM_JOINT6" type="revolute">
    <parent link="RARM_LINK5"/>
    <child  link="RARM_LINK6"/>
    <origin xyz="0.0315 -0.0105 0" rpy="0 -0 0 "/>
    <axis   xyz="0 0 -1"/>
    <limit lower="-1.74533" upper="1.74533" effort="0.656248" velocity="7.47998" />
    <dynamics damping="0.2" friction="0" />
  </joint>
  <joint name="RARM_JOINT7" type="revolute">
    <parent link="RARM_LINK5"/>
    <child  link="RARM_LINK7"/>
    <origin xyz="0.0315 0.012979 0" rpy="0 -0 0 "/>
    <axis   xyz="4.44089e-16 0 1"/>
    <limit lower="-1.74533" upper="1.74533" effort="0.656248" velocity="7.47998" />
    <!-- <mimic joint="RARM_JOINT6" multiplier="-1" /> -->
    <dynamics damping="0.2" friction="0" />
  </joint>
  <joint name="RLEG_JOINT0" type="revolute">
    <parent link="bodyset94472077639384"/>
    <child  link="RLEG_LINK0"/>
    <origin xyz="0 -0.034 -0.0565" rpy="0 -0 0 "/>
    <axis   xyz="0 0 1"/>
    <limit lower="-1.91986" upper="1.91986" effort="0.656248" velocity="7.47998" />
    <dynamics damping="0.2" friction="0" />
  </joint>
  <joint name="RLEG_JOINT1" type="revolute">
    <parent link="RLEG_LINK0"/>
    <child  link="RLEG_LINK1"/>
    <origin xyz="0 0 -0.033" rpy="0 -0 0 "/>
    <axis   xyz="-1 0 0"/>
    <limit lower="-1.91986" upper="1.91986" effort="0.656248" velocity="7.47998" />
    <dynamics damping="0.2" friction="0" />
  </joint>
</robot>
